# 错误、调试和测试

## try

```python
try:
    print('try...')
    r = 10/0
    print('result:',r)
except ZeroDivisionError as e:
    print('except',e)
finally:
    print('finally')

```

当我们认为某些代码可能会出错时，就可以用`try`来运行这段代码，如果执行出错，则后续代码不会继续执行，而是直接跳转至错误处理代码，即`except`语句块，执行完`except`后，如果有`finally`语句块，则执行`finally`语句块，至此，执行完毕。

 ```python
try...
except: division by zero
finally...
 ```



## 常见的错误类型和继承关系

Python所有的错误都是从`BaseException`类派生的，**常见的错误类型和继承关系**看这里：

```
BaseException
 +-- SystemExit
 +-- KeyboardInterrupt
 +-- GeneratorExit
 +-- Exception
      +-- StopIteration
      +-- StopAsyncIteration
      +-- ArithmeticError
      |    +-- FloatingPointError
      |    +-- OverflowError
      |    +-- ZeroDivisionError
      +-- AssertionError
      +-- AttributeError
      +-- BufferError
      +-- EOFError
      +-- ImportError
      |    +-- ModuleNotFoundError
      +-- LookupError
      |    +-- IndexError
      |    +-- KeyError
      +-- MemoryError
      +-- NameError
      |    +-- UnboundLocalError
      +-- OSError
      |    +-- BlockingIOError
      |    +-- ChildProcessError
      |    +-- ConnectionError
      |    |    +-- BrokenPipeError
      |    |    +-- ConnectionAbortedError
      |    |    +-- ConnectionRefusedError
      |    |    +-- ConnectionResetError
      |    +-- FileExistsError
      |    +-- FileNotFoundError
      |    +-- InterruptedError
      |    +-- IsADirectoryError
      |    +-- NotADirectoryError
      |    +-- PermissionError
      |    +-- ProcessLookupError
      |    +-- TimeoutError
      +-- ReferenceError
      +-- RuntimeError
      |    +-- NotImplementedError
      |    +-- RecursionError
      +-- SyntaxError
      |    +-- IndentationError
      |         +-- TabError
      +-- SystemError
      +-- TypeError
      +-- ValueError
      |    +-- UnicodeError
      |         +-- UnicodeDecodeError
      |         +-- UnicodeEncodeError
      |         +-- UnicodeTranslateError
      +-- Warning
           +-- DeprecationWarning
           +-- PendingDeprecationWarning
           +-- RuntimeWarning
           +-- SyntaxWarning
           +-- UserWarning
           +-- FutureWarning
           +-- ImportWarning
           +-- UnicodeWarning
           +-- BytesWarning
           +-- ResourceWarning
```

## 主动抛出异常

如果要抛出错误，首先根据需要，可以定义一个错误的class，选择好继承关系，然后，用`raise`语句抛出一个错误的实例：

 ```python
class FooError(ValueError):
    pass
def Foo(s):
    n = int(s)
    if n == 0:
        raise FooError('invalid Error is %s'%s)
    return 10/n
Foo('0')
 ```

```python
Traceback (most recent call last):
  File "/Users/wangzhen/PycharmProjects/错误调试/try_test.py", line 8, in <module>
    Foo('0')
  File "/Users/wangzhen/PycharmProjects/错误调试/try_test.py", line 6, in Foo
    raise FooError('invalid Error is %s'%s)
__main__.FooError: invalid Error is 0

```

只有在必要的时候才定义我们自己的错误类型。如果可以选择Python已有的内置的错误类型（比如`ValueError`，`TypeError`），尽量使用Python内置的错误类型。

##  断言assert

用`print()`最大的坏处是将来还得删掉它，想想程序里到处都是`print()`，运行结果也会包含很多垃圾信息。所以，我们又有第二种方法。

 凡是用`print()`来辅助查看的地方，都可以用断言（assert）来替代：

 ```python
def foo(s):
    n = int(s)
    assert n != 0, 'n is zero!'
    return 10 / n

def main():
    foo('0')
 ```

程序中如果到处充斥着`assert`，和`print()`相比也好不到哪去。不过，启动Python解释器时可以用`-O`参数来关闭`assert`：

 ```python
$ python -O err.py
Traceback (most recent call last):
  ...
ZeroDivisionError: division by zero
 ```

关闭后，可以将所有的`assert`语句当成`pass`来看



